[2024-11-23T11:11:11.318+0000] {local_task_job_runner.py:123} INFO - ::group::Pre task execution logs
[2024-11-23T11:11:11.344+0000] {taskinstance.py:2613} INFO - Dependencies all met for dep_context=non-requeueable deps ti=<TaskInstance: api_to_postgresql_2.transform_attendance_data manual__2024-11-23T11:10:00.362258+00:00 [queued]>
[2024-11-23T11:11:11.354+0000] {taskinstance.py:2613} INFO - Dependencies all met for dep_context=requeueable deps ti=<TaskInstance: api_to_postgresql_2.transform_attendance_data manual__2024-11-23T11:10:00.362258+00:00 [queued]>
[2024-11-23T11:11:11.355+0000] {taskinstance.py:2866} INFO - Starting attempt 1 of 3
[2024-11-23T11:11:11.372+0000] {taskinstance.py:2889} INFO - Executing <Task(_PythonDecoratedOperator): transform_attendance_data> on 2024-11-23 11:10:00.362258+00:00
[2024-11-23T11:11:11.385+0000] {logging_mixin.py:190} WARNING - /home/***/.local/lib/python3.12/site-packages/***/task/task_runner/standard_task_runner.py:70 DeprecationWarning: This process (pid=39319) is multi-threaded, use of fork() may lead to deadlocks in the child.
[2024-11-23T11:11:11.385+0000] {standard_task_runner.py:104} INFO - Running: ['***', 'tasks', 'run', 'api_to_postgresql_2', 'transform_attendance_data', 'manual__2024-11-23T11:10:00.362258+00:00', '--job-id', '12', '--raw', '--subdir', 'DAGS_FOLDER/api_to_pgdatabase.py', '--cfg-path', '/tmp/tmpk2qzavl0']
[2024-11-23T11:11:11.387+0000] {standard_task_runner.py:72} INFO - Started process 39320 to run task
[2024-11-23T11:11:11.387+0000] {standard_task_runner.py:105} INFO - Job 12: Subtask transform_attendance_data
[2024-11-23T11:11:11.442+0000] {task_command.py:467} INFO - Running <TaskInstance: api_to_postgresql_2.transform_attendance_data manual__2024-11-23T11:10:00.362258+00:00 [running]> on host 4549f6bb77d2
[2024-11-23T11:11:11.554+0000] {taskinstance.py:3132} INFO - Exporting env vars: AIRFLOW_CTX_DAG_OWNER='***' AIRFLOW_CTX_DAG_ID='api_to_postgresql_2' AIRFLOW_CTX_TASK_ID='transform_attendance_data' AIRFLOW_CTX_EXECUTION_DATE='2024-11-23T11:10:00.362258+00:00' AIRFLOW_CTX_TRY_NUMBER='1' AIRFLOW_CTX_DAG_RUN_ID='manual__2024-11-23T11:10:00.362258+00:00'
[2024-11-23T11:11:11.556+0000] {logging_mixin.py:190} INFO - Task instance is in running state
[2024-11-23T11:11:11.556+0000] {logging_mixin.py:190} INFO -  Previous state of the Task instance: queued
[2024-11-23T11:11:11.557+0000] {logging_mixin.py:190} INFO - Current task name:transform_attendance_data state:running start_date:2024-11-23 11:11:11.345059+00:00
[2024-11-23T11:11:11.557+0000] {logging_mixin.py:190} INFO - Dag name:api_to_postgresql_2 and current dag run status:running
[2024-11-23T11:11:11.558+0000] {taskinstance.py:731} INFO - ::endgroup::
[2024-11-23T11:11:11.559+0000] {taskinstance.py:3311} ERROR - Task failed with exception
Traceback (most recent call last):
  File "/home/airflow/.local/lib/python3.12/site-packages/airflow/models/taskinstance.py", line 767, in _execute_task
    result = _execute_callable(context=context, **execute_callable_kwargs)
             ^^^^^^^^^^^^^^^^^^^^^^^^^^^^^^^^^^^^^^^^^^^^^^^^^^^^^^^^^^^^^
  File "/home/airflow/.local/lib/python3.12/site-packages/airflow/models/taskinstance.py", line 733, in _execute_callable
    return ExecutionCallableRunner(
           ^^^^^^^^^^^^^^^^^^^^^^^^
  File "/home/airflow/.local/lib/python3.12/site-packages/airflow/utils/operator_helpers.py", line 252, in run
    return self.func(*args, **kwargs)
           ^^^^^^^^^^^^^^^^^^^^^^^^^^
  File "/home/airflow/.local/lib/python3.12/site-packages/airflow/models/baseoperator.py", line 417, in wrapper
    return func(self, *args, **kwargs)
           ^^^^^^^^^^^^^^^^^^^^^^^^^^^
  File "/home/airflow/.local/lib/python3.12/site-packages/airflow/decorators/base.py", line 266, in execute
    return_value = super().execute(context)
                   ^^^^^^^^^^^^^^^^^^^^^^^^
  File "/home/airflow/.local/lib/python3.12/site-packages/airflow/models/baseoperator.py", line 417, in wrapper
    return func(self, *args, **kwargs)
           ^^^^^^^^^^^^^^^^^^^^^^^^^^^
  File "/home/airflow/.local/lib/python3.12/site-packages/airflow/operators/python.py", line 238, in execute
    return_value = self.execute_callable()
                   ^^^^^^^^^^^^^^^^^^^^^^^
  File "/home/airflow/.local/lib/python3.12/site-packages/airflow/operators/python.py", line 256, in execute_callable
    return runner.run(*self.op_args, **self.op_kwargs)
           ^^^^^^^^^^^^^^^^^^^^^^^^^^^^^^^^^^^^^^^^^^^
  File "/home/airflow/.local/lib/python3.12/site-packages/airflow/utils/operator_helpers.py", line 252, in run
    return self.func(*args, **kwargs)
           ^^^^^^^^^^^^^^^^^^^^^^^^^^
  File "/opt/airflow/dags/api_to_pgdatabase.py", line 80, in transform_attendance_data
    'in_datetime': record['InDateTime'],
                   ~~~~~~^^^^^^^^^^^^^^
KeyError: 'InDateTime'
[2024-11-23T11:11:11.576+0000] {logging_mixin.py:190} INFO - Task instance in failure state
[2024-11-23T11:11:11.577+0000] {logging_mixin.py:190} INFO - Task start:2024-11-23 11:11:11.345059+00:00 end:2024-11-23 11:11:11.575905+00:00 duration:0.230846
[2024-11-23T11:11:11.577+0000] {logging_mixin.py:190} INFO - Task:<Task(_PythonDecoratedOperator): transform_attendance_data> dag:<DAG: api_to_postgresql_2> dagrun:<DagRun api_to_postgresql_2 @ 2024-11-23 11:10:00.362258+00:00: manual__2024-11-23T11:10:00.362258+00:00, state:running, queued_at: 2024-11-23 11:10:00.415667+00:00. externally triggered: True>
[2024-11-23T11:11:11.577+0000] {logging_mixin.py:190} INFO - Failure caused by 'InDateTime'
[2024-11-23T11:11:11.578+0000] {taskinstance.py:1225} INFO - Marking task as UP_FOR_RETRY. dag_id=api_to_postgresql_2, task_id=transform_attendance_data, run_id=manual__2024-11-23T11:10:00.362258+00:00, execution_date=20241123T111000, start_date=20241123T111111, end_date=20241123T111111
[2024-11-23T11:11:11.593+0000] {taskinstance.py:340} INFO - ::group::Post task execution logs
[2024-11-23T11:11:11.594+0000] {standard_task_runner.py:124} ERROR - Failed to execute job 12 for task transform_attendance_data ('InDateTime'; 39320)
Traceback (most recent call last):
  File "/home/airflow/.local/lib/python3.12/site-packages/airflow/task/task_runner/standard_task_runner.py", line 117, in _start_by_fork
    ret = args.func(args, dag=self.dag)
          ^^^^^^^^^^^^^^^^^^^^^^^^^^^^^
  File "/home/airflow/.local/lib/python3.12/site-packages/airflow/cli/cli_config.py", line 49, in command
    return func(*args, **kwargs)
           ^^^^^^^^^^^^^^^^^^^^^
  File "/home/airflow/.local/lib/python3.12/site-packages/airflow/utils/cli.py", line 116, in wrapper
    return f(*args, **kwargs)
           ^^^^^^^^^^^^^^^^^^
  File "/home/airflow/.local/lib/python3.12/site-packages/airflow/cli/commands/task_command.py", line 483, in task_run
    task_return_code = _run_task_by_selected_method(args, _dag, ti)
                       ^^^^^^^^^^^^^^^^^^^^^^^^^^^^^^^^^^^^^^^^^^^^
  File "/home/airflow/.local/lib/python3.12/site-packages/airflow/cli/commands/task_command.py", line 256, in _run_task_by_selected_method
    return _run_raw_task(args, ti)
           ^^^^^^^^^^^^^^^^^^^^^^^
  File "/home/airflow/.local/lib/python3.12/site-packages/airflow/cli/commands/task_command.py", line 341, in _run_raw_task
    return ti._run_raw_task(
           ^^^^^^^^^^^^^^^^^
  File "/home/airflow/.local/lib/python3.12/site-packages/airflow/utils/session.py", line 97, in wrapper
    return func(*args, session=session, **kwargs)
           ^^^^^^^^^^^^^^^^^^^^^^^^^^^^^^^^^^^^^^
  File "/home/airflow/.local/lib/python3.12/site-packages/airflow/models/taskinstance.py", line 3005, in _run_raw_task
    return _run_raw_task(
           ^^^^^^^^^^^^^^
  File "/home/airflow/.local/lib/python3.12/site-packages/airflow/models/taskinstance.py", line 273, in _run_raw_task
    TaskInstance._execute_task_with_callbacks(
  File "/home/airflow/.local/lib/python3.12/site-packages/airflow/models/taskinstance.py", line 3159, in _execute_task_with_callbacks
    result = self._execute_task(context, task_orig)
             ^^^^^^^^^^^^^^^^^^^^^^^^^^^^^^^^^^^^^^
  File "/home/airflow/.local/lib/python3.12/site-packages/airflow/models/taskinstance.py", line 3183, in _execute_task
    return _execute_task(self, context, task_orig)
           ^^^^^^^^^^^^^^^^^^^^^^^^^^^^^^^^^^^^^^^
  File "/home/airflow/.local/lib/python3.12/site-packages/airflow/models/taskinstance.py", line 767, in _execute_task
    result = _execute_callable(context=context, **execute_callable_kwargs)
             ^^^^^^^^^^^^^^^^^^^^^^^^^^^^^^^^^^^^^^^^^^^^^^^^^^^^^^^^^^^^^
  File "/home/airflow/.local/lib/python3.12/site-packages/airflow/models/taskinstance.py", line 733, in _execute_callable
    return ExecutionCallableRunner(
           ^^^^^^^^^^^^^^^^^^^^^^^^
  File "/home/airflow/.local/lib/python3.12/site-packages/airflow/utils/operator_helpers.py", line 252, in run
    return self.func(*args, **kwargs)
           ^^^^^^^^^^^^^^^^^^^^^^^^^^
  File "/home/airflow/.local/lib/python3.12/site-packages/airflow/models/baseoperator.py", line 417, in wrapper
    return func(self, *args, **kwargs)
           ^^^^^^^^^^^^^^^^^^^^^^^^^^^
  File "/home/airflow/.local/lib/python3.12/site-packages/airflow/decorators/base.py", line 266, in execute
    return_value = super().execute(context)
                   ^^^^^^^^^^^^^^^^^^^^^^^^
  File "/home/airflow/.local/lib/python3.12/site-packages/airflow/models/baseoperator.py", line 417, in wrapper
    return func(self, *args, **kwargs)
           ^^^^^^^^^^^^^^^^^^^^^^^^^^^
  File "/home/airflow/.local/lib/python3.12/site-packages/airflow/operators/python.py", line 238, in execute
    return_value = self.execute_callable()
                   ^^^^^^^^^^^^^^^^^^^^^^^
  File "/home/airflow/.local/lib/python3.12/site-packages/airflow/operators/python.py", line 256, in execute_callable
    return runner.run(*self.op_args, **self.op_kwargs)
           ^^^^^^^^^^^^^^^^^^^^^^^^^^^^^^^^^^^^^^^^^^^
  File "/home/airflow/.local/lib/python3.12/site-packages/airflow/utils/operator_helpers.py", line 252, in run
    return self.func(*args, **kwargs)
           ^^^^^^^^^^^^^^^^^^^^^^^^^^
  File "/opt/airflow/dags/api_to_pgdatabase.py", line 80, in transform_attendance_data
    'in_datetime': record['InDateTime'],
                   ~~~~~~^^^^^^^^^^^^^^
KeyError: 'InDateTime'
[2024-11-23T11:11:11.642+0000] {local_task_job_runner.py:266} INFO - Task exited with return code 1
[2024-11-23T11:11:11.667+0000] {taskinstance.py:3895} INFO - 0 downstream tasks scheduled from follow-on schedule check
[2024-11-23T11:11:11.670+0000] {local_task_job_runner.py:245} INFO - ::endgroup::
