[2024-11-23T08:36:24.759+0000] {local_task_job_runner.py:123} INFO - ::group::Pre task execution logs
[2024-11-23T08:36:24.795+0000] {taskinstance.py:2613} INFO - Dependencies all met for dep_context=non-requeueable deps ti=<TaskInstance: fetch_data_from_api_to_postgresql.store_data_to_postgresql scheduled__2024-11-23T08:00:00+00:00 [queued]>
[2024-11-23T08:36:24.818+0000] {taskinstance.py:2613} INFO - Dependencies all met for dep_context=requeueable deps ti=<TaskInstance: fetch_data_from_api_to_postgresql.store_data_to_postgresql scheduled__2024-11-23T08:00:00+00:00 [queued]>
[2024-11-23T08:36:24.820+0000] {taskinstance.py:2866} INFO - Starting attempt 1 of 3
[2024-11-23T08:36:24.863+0000] {taskinstance.py:2889} INFO - Executing <Task(PythonOperator): store_data_to_postgresql> on 2024-11-23 08:00:00+00:00
[2024-11-23T08:36:24.905+0000] {logging_mixin.py:190} WARNING - /home/***/.local/lib/python3.12/site-packages/***/task/task_runner/standard_task_runner.py:70 DeprecationWarning: This process (pid=52585) is multi-threaded, use of fork() may lead to deadlocks in the child.
[2024-11-23T08:36:24.910+0000] {standard_task_runner.py:72} INFO - Started process 52586 to run task
[2024-11-23T08:36:24.907+0000] {standard_task_runner.py:104} INFO - Running: ['***', 'tasks', 'run', 'fetch_data_from_api_to_postgresql', 'store_data_to_postgresql', 'scheduled__2024-11-23T08:00:00+00:00', '--job-id', '5', '--raw', '--subdir', 'DAGS_FOLDER/api_to_pgdatabase.py', '--cfg-path', '/tmp/tmpwgtdot_o']
[2024-11-23T08:36:24.916+0000] {standard_task_runner.py:105} INFO - Job 5: Subtask store_data_to_postgresql
[2024-11-23T08:36:25.158+0000] {task_command.py:467} INFO - Running <TaskInstance: fetch_data_from_api_to_postgresql.store_data_to_postgresql scheduled__2024-11-23T08:00:00+00:00 [running]> on host 4549f6bb77d2
[2024-11-23T08:36:25.643+0000] {taskinstance.py:3132} INFO - Exporting env vars: AIRFLOW_CTX_DAG_OWNER='***' AIRFLOW_CTX_DAG_ID='fetch_data_from_api_to_postgresql' AIRFLOW_CTX_TASK_ID='store_data_to_postgresql' AIRFLOW_CTX_EXECUTION_DATE='2024-11-23T08:00:00+00:00' AIRFLOW_CTX_TRY_NUMBER='1' AIRFLOW_CTX_DAG_RUN_ID='scheduled__2024-11-23T08:00:00+00:00'
[2024-11-23T08:36:25.647+0000] {logging_mixin.py:190} INFO - Task instance is in running state
[2024-11-23T08:36:25.648+0000] {logging_mixin.py:190} INFO -  Previous state of the Task instance: queued
[2024-11-23T08:36:25.650+0000] {logging_mixin.py:190} INFO - Current task name:store_data_to_postgresql state:running start_date:2024-11-23 08:36:24.797024+00:00
[2024-11-23T08:36:25.651+0000] {logging_mixin.py:190} INFO - Dag name:fetch_data_from_api_to_postgresql and current dag run status:running
[2024-11-23T08:36:25.652+0000] {taskinstance.py:731} INFO - ::endgroup::
[2024-11-23T08:36:25.718+0000] {base.py:84} INFO - Retrieving connection 'postgres_default_2'
[2024-11-23T08:36:25.935+0000] {taskinstance.py:3311} ERROR - Task failed with exception
Traceback (most recent call last):
  File "/home/airflow/.local/lib/python3.12/site-packages/airflow/models/taskinstance.py", line 767, in _execute_task
    result = _execute_callable(context=context, **execute_callable_kwargs)
             ^^^^^^^^^^^^^^^^^^^^^^^^^^^^^^^^^^^^^^^^^^^^^^^^^^^^^^^^^^^^^
  File "/home/airflow/.local/lib/python3.12/site-packages/airflow/models/taskinstance.py", line 733, in _execute_callable
    return ExecutionCallableRunner(
           ^^^^^^^^^^^^^^^^^^^^^^^^
  File "/home/airflow/.local/lib/python3.12/site-packages/airflow/utils/operator_helpers.py", line 252, in run
    return self.func(*args, **kwargs)
           ^^^^^^^^^^^^^^^^^^^^^^^^^^
  File "/home/airflow/.local/lib/python3.12/site-packages/airflow/models/baseoperator.py", line 417, in wrapper
    return func(self, *args, **kwargs)
           ^^^^^^^^^^^^^^^^^^^^^^^^^^^
  File "/home/airflow/.local/lib/python3.12/site-packages/airflow/operators/python.py", line 238, in execute
    return_value = self.execute_callable()
                   ^^^^^^^^^^^^^^^^^^^^^^^
  File "/home/airflow/.local/lib/python3.12/site-packages/airflow/operators/python.py", line 256, in execute_callable
    return runner.run(*self.op_args, **self.op_kwargs)
           ^^^^^^^^^^^^^^^^^^^^^^^^^^^^^^^^^^^^^^^^^^^
  File "/home/airflow/.local/lib/python3.12/site-packages/airflow/utils/operator_helpers.py", line 252, in run
    return self.func(*args, **kwargs)
           ^^^^^^^^^^^^^^^^^^^^^^^^^^
  File "/opt/airflow/dags/api_to_pgdatabase.py", line 126, in store_data_to_postgresql
    cursor.execute(
psycopg2.errors.UndefinedTable: relation "attendance" does not exist
LINE 2:         INSERT INTO attendance (
                            ^

[2024-11-23T08:36:26.234+0000] {logging_mixin.py:190} INFO - Task instance in failure state
[2024-11-23T08:36:26.238+0000] {logging_mixin.py:190} INFO - Task start:2024-11-23 08:36:24.797024+00:00 end:2024-11-23 08:36:26.186116+00:00 duration:1.389092
[2024-11-23T08:36:26.246+0000] {logging_mixin.py:190} INFO - Task:<Task(PythonOperator): store_data_to_postgresql> dag:<DAG: fetch_data_from_api_to_postgresql> dagrun:<DagRun fetch_data_from_api_to_postgresql @ 2024-11-23 08:00:00+00:00: scheduled__2024-11-23T08:00:00+00:00, state:running, queued_at: 2024-11-23 08:35:15.239985+00:00. externally triggered: False>
[2024-11-23T08:36:26.247+0000] {logging_mixin.py:190} INFO - Failure caused by relation "attendance" does not exist
LINE 2:         INSERT INTO attendance (
                            ^
[2024-11-23T08:36:26.253+0000] {taskinstance.py:1225} INFO - Marking task as UP_FOR_RETRY. dag_id=fetch_data_from_api_to_postgresql, task_id=store_data_to_postgresql, run_id=scheduled__2024-11-23T08:00:00+00:00, execution_date=20241123T080000, start_date=20241123T083624, end_date=20241123T083626
[2024-11-23T08:36:26.355+0000] {taskinstance.py:340} INFO - ::group::Post task execution logs
[2024-11-23T08:36:26.359+0000] {standard_task_runner.py:124} ERROR - Failed to execute job 5 for task store_data_to_postgresql (relation "attendance" does not exist
LINE 2:         INSERT INTO attendance (
                            ^
; 52586)
Traceback (most recent call last):
  File "/home/airflow/.local/lib/python3.12/site-packages/airflow/task/task_runner/standard_task_runner.py", line 117, in _start_by_fork
    ret = args.func(args, dag=self.dag)
          ^^^^^^^^^^^^^^^^^^^^^^^^^^^^^
  File "/home/airflow/.local/lib/python3.12/site-packages/airflow/cli/cli_config.py", line 49, in command
    return func(*args, **kwargs)
           ^^^^^^^^^^^^^^^^^^^^^
  File "/home/airflow/.local/lib/python3.12/site-packages/airflow/utils/cli.py", line 116, in wrapper
    return f(*args, **kwargs)
           ^^^^^^^^^^^^^^^^^^
  File "/home/airflow/.local/lib/python3.12/site-packages/airflow/cli/commands/task_command.py", line 483, in task_run
    task_return_code = _run_task_by_selected_method(args, _dag, ti)
                       ^^^^^^^^^^^^^^^^^^^^^^^^^^^^^^^^^^^^^^^^^^^^
  File "/home/airflow/.local/lib/python3.12/site-packages/airflow/cli/commands/task_command.py", line 256, in _run_task_by_selected_method
    return _run_raw_task(args, ti)
           ^^^^^^^^^^^^^^^^^^^^^^^
  File "/home/airflow/.local/lib/python3.12/site-packages/airflow/cli/commands/task_command.py", line 341, in _run_raw_task
    return ti._run_raw_task(
           ^^^^^^^^^^^^^^^^^
  File "/home/airflow/.local/lib/python3.12/site-packages/airflow/utils/session.py", line 97, in wrapper
    return func(*args, session=session, **kwargs)
           ^^^^^^^^^^^^^^^^^^^^^^^^^^^^^^^^^^^^^^
  File "/home/airflow/.local/lib/python3.12/site-packages/airflow/models/taskinstance.py", line 3005, in _run_raw_task
    return _run_raw_task(
           ^^^^^^^^^^^^^^
  File "/home/airflow/.local/lib/python3.12/site-packages/airflow/models/taskinstance.py", line 273, in _run_raw_task
    TaskInstance._execute_task_with_callbacks(
  File "/home/airflow/.local/lib/python3.12/site-packages/airflow/models/taskinstance.py", line 3159, in _execute_task_with_callbacks
    result = self._execute_task(context, task_orig)
             ^^^^^^^^^^^^^^^^^^^^^^^^^^^^^^^^^^^^^^
  File "/home/airflow/.local/lib/python3.12/site-packages/airflow/models/taskinstance.py", line 3183, in _execute_task
    return _execute_task(self, context, task_orig)
           ^^^^^^^^^^^^^^^^^^^^^^^^^^^^^^^^^^^^^^^
  File "/home/airflow/.local/lib/python3.12/site-packages/airflow/models/taskinstance.py", line 767, in _execute_task
    result = _execute_callable(context=context, **execute_callable_kwargs)
             ^^^^^^^^^^^^^^^^^^^^^^^^^^^^^^^^^^^^^^^^^^^^^^^^^^^^^^^^^^^^^
  File "/home/airflow/.local/lib/python3.12/site-packages/airflow/models/taskinstance.py", line 733, in _execute_callable
    return ExecutionCallableRunner(
           ^^^^^^^^^^^^^^^^^^^^^^^^
  File "/home/airflow/.local/lib/python3.12/site-packages/airflow/utils/operator_helpers.py", line 252, in run
    return self.func(*args, **kwargs)
           ^^^^^^^^^^^^^^^^^^^^^^^^^^
  File "/home/airflow/.local/lib/python3.12/site-packages/airflow/models/baseoperator.py", line 417, in wrapper
    return func(self, *args, **kwargs)
           ^^^^^^^^^^^^^^^^^^^^^^^^^^^
  File "/home/airflow/.local/lib/python3.12/site-packages/airflow/operators/python.py", line 238, in execute
    return_value = self.execute_callable()
                   ^^^^^^^^^^^^^^^^^^^^^^^
  File "/home/airflow/.local/lib/python3.12/site-packages/airflow/operators/python.py", line 256, in execute_callable
    return runner.run(*self.op_args, **self.op_kwargs)
           ^^^^^^^^^^^^^^^^^^^^^^^^^^^^^^^^^^^^^^^^^^^
  File "/home/airflow/.local/lib/python3.12/site-packages/airflow/utils/operator_helpers.py", line 252, in run
    return self.func(*args, **kwargs)
           ^^^^^^^^^^^^^^^^^^^^^^^^^^
  File "/opt/airflow/dags/api_to_pgdatabase.py", line 126, in store_data_to_postgresql
    cursor.execute(
psycopg2.errors.UndefinedTable: relation "attendance" does not exist
LINE 2:         INSERT INTO attendance (
                            ^

[2024-11-23T08:36:26.423+0000] {local_task_job_runner.py:266} INFO - Task exited with return code 1
[2024-11-23T08:36:26.596+0000] {taskinstance.py:3895} INFO - 0 downstream tasks scheduled from follow-on schedule check
[2024-11-23T08:36:26.601+0000] {local_task_job_runner.py:245} INFO - ::endgroup::
