[2024-11-25T08:42:43.072+0000] {local_task_job_runner.py:123} INFO - ::group::Pre task execution logs
[2024-11-25T08:42:43.109+0000] {taskinstance.py:2613} INFO - Dependencies all met for dep_context=non-requeueable deps ti=<TaskInstance: api_to_postgresql_2.extract_attendance_data scheduled__2024-11-24T00:00:00+00:00 [queued]>
[2024-11-25T08:42:43.125+0000] {taskinstance.py:2613} INFO - Dependencies all met for dep_context=requeueable deps ti=<TaskInstance: api_to_postgresql_2.extract_attendance_data scheduled__2024-11-24T00:00:00+00:00 [queued]>
[2024-11-25T08:42:43.126+0000] {taskinstance.py:2866} INFO - Starting attempt 1 of 3
[2024-11-25T08:42:43.166+0000] {taskinstance.py:2889} INFO - Executing <Task(_PythonDecoratedOperator): extract_attendance_data> on 2024-11-24 00:00:00+00:00
[2024-11-25T08:42:43.198+0000] {logging_mixin.py:190} WARNING - /home/***/.local/lib/python3.12/site-packages/***/task/task_runner/standard_task_runner.py:70 DeprecationWarning: This process (pid=970) is multi-threaded, use of fork() may lead to deadlocks in the child.
[2024-11-25T08:42:43.198+0000] {standard_task_runner.py:104} INFO - Running: ['***', 'tasks', 'run', 'api_to_postgresql_2', 'extract_attendance_data', 'scheduled__2024-11-24T00:00:00+00:00', '--job-id', '3', '--raw', '--subdir', 'DAGS_FOLDER/api_to_pgdatabase.py', '--cfg-path', '/tmp/tmpwhil2nre']
[2024-11-25T08:42:43.201+0000] {standard_task_runner.py:72} INFO - Started process 1035 to run task
[2024-11-25T08:42:43.202+0000] {standard_task_runner.py:105} INFO - Job 3: Subtask extract_attendance_data
[2024-11-25T08:42:43.637+0000] {task_command.py:467} INFO - Running <TaskInstance: api_to_postgresql_2.extract_attendance_data scheduled__2024-11-24T00:00:00+00:00 [running]> on host 06d2a9f4732f
[2024-11-25T08:42:43.838+0000] {taskinstance.py:3132} INFO - Exporting env vars: AIRFLOW_CTX_DAG_OWNER='***' AIRFLOW_CTX_DAG_ID='api_to_postgresql_2' AIRFLOW_CTX_TASK_ID='extract_attendance_data' AIRFLOW_CTX_EXECUTION_DATE='2024-11-24T00:00:00+00:00' AIRFLOW_CTX_TRY_NUMBER='1' AIRFLOW_CTX_DAG_RUN_ID='scheduled__2024-11-24T00:00:00+00:00'
[2024-11-25T08:42:43.841+0000] {logging_mixin.py:190} INFO - Task instance is in running state
[2024-11-25T08:42:43.842+0000] {logging_mixin.py:190} INFO -  Previous state of the Task instance: queued
[2024-11-25T08:42:43.844+0000] {logging_mixin.py:190} INFO - Current task name:extract_attendance_data state:running start_date:2024-11-25 08:42:43.110613+00:00
[2024-11-25T08:42:43.845+0000] {logging_mixin.py:190} INFO - Dag name:api_to_postgresql_2 and current dag run status:running
[2024-11-25T08:42:43.846+0000] {taskinstance.py:731} INFO - ::endgroup::
[2024-11-25T08:42:43.908+0000] {taskinstance.py:3311} ERROR - Task failed with exception
Traceback (most recent call last):
  File "/home/airflow/.local/lib/python3.12/site-packages/airflow/models/taskinstance.py", line 767, in _execute_task
    result = _execute_callable(context=context, **execute_callable_kwargs)
             ^^^^^^^^^^^^^^^^^^^^^^^^^^^^^^^^^^^^^^^^^^^^^^^^^^^^^^^^^^^^^
  File "/home/airflow/.local/lib/python3.12/site-packages/airflow/models/taskinstance.py", line 733, in _execute_callable
    return ExecutionCallableRunner(
           ^^^^^^^^^^^^^^^^^^^^^^^^
  File "/home/airflow/.local/lib/python3.12/site-packages/airflow/utils/operator_helpers.py", line 252, in run
    return self.func(*args, **kwargs)
           ^^^^^^^^^^^^^^^^^^^^^^^^^^
  File "/home/airflow/.local/lib/python3.12/site-packages/airflow/models/baseoperator.py", line 417, in wrapper
    return func(self, *args, **kwargs)
           ^^^^^^^^^^^^^^^^^^^^^^^^^^^
  File "/home/airflow/.local/lib/python3.12/site-packages/airflow/decorators/base.py", line 266, in execute
    return_value = super().execute(context)
                   ^^^^^^^^^^^^^^^^^^^^^^^^
  File "/home/airflow/.local/lib/python3.12/site-packages/airflow/models/baseoperator.py", line 417, in wrapper
    return func(self, *args, **kwargs)
           ^^^^^^^^^^^^^^^^^^^^^^^^^^^
  File "/home/airflow/.local/lib/python3.12/site-packages/airflow/operators/python.py", line 238, in execute
    return_value = self.execute_callable()
                   ^^^^^^^^^^^^^^^^^^^^^^^
  File "/home/airflow/.local/lib/python3.12/site-packages/airflow/operators/python.py", line 256, in execute_callable
    return runner.run(*self.op_args, **self.op_kwargs)
           ^^^^^^^^^^^^^^^^^^^^^^^^^^^^^^^^^^^^^^^^^^^
  File "/home/airflow/.local/lib/python3.12/site-packages/airflow/utils/operator_helpers.py", line 252, in run
    return self.func(*args, **kwargs)
           ^^^^^^^^^^^^^^^^^^^^^^^^^^
  File "/opt/airflow/dags/api_to_pgdatabase.py", line 48, in extract_attendance_data
    response=http_hook.run(endpoint)
             ^^^^^^^^^^^^^^^^^^^^^^^
  File "/home/airflow/.local/lib/python3.12/site-packages/airflow/providers/http/hooks/http.py", line 170, in run
    session = self.get_conn(headers)
              ^^^^^^^^^^^^^^^^^^^^^^
  File "/home/airflow/.local/lib/python3.12/site-packages/airflow/providers/http/hooks/http.py", line 110, in get_conn
    conn = self.get_connection(self.http_conn_id)
           ^^^^^^^^^^^^^^^^^^^^^^^^^^^^^^^^^^^^^^
  File "/home/airflow/.local/lib/python3.12/site-packages/airflow/hooks/base.py", line 83, in get_connection
    conn = Connection.get_connection_from_secrets(conn_id)
           ^^^^^^^^^^^^^^^^^^^^^^^^^^^^^^^^^^^^^^^^^^^^^^^
  File "/home/airflow/.local/lib/python3.12/site-packages/airflow/models/connection.py", line 537, in get_connection_from_secrets
    raise AirflowNotFoundException(f"The conn_id `{conn_id}` isn't defined")
airflow.exceptions.AirflowNotFoundException: The conn_id `attendance_api` isn't defined
[2024-11-25T08:42:43.956+0000] {logging_mixin.py:190} INFO - Task instance in failure state
[2024-11-25T08:42:43.957+0000] {logging_mixin.py:190} INFO - Task start:2024-11-25 08:42:43.110613+00:00 end:2024-11-25 08:42:43.955333+00:00 duration:0.84472
[2024-11-25T08:42:43.959+0000] {logging_mixin.py:190} INFO - Task:<Task(_PythonDecoratedOperator): extract_attendance_data> dag:<DAG: api_to_postgresql_2> dagrun:<DagRun api_to_postgresql_2 @ 2024-11-24 00:00:00+00:00: scheduled__2024-11-24T00:00:00+00:00, state:running, queued_at: 2024-11-25 08:42:39.434222+00:00. externally triggered: False>
[2024-11-25T08:42:43.959+0000] {logging_mixin.py:190} INFO - Failure caused by The conn_id `attendance_api` isn't defined
[2024-11-25T08:42:43.960+0000] {taskinstance.py:1225} INFO - Marking task as UP_FOR_RETRY. dag_id=api_to_postgresql_2, task_id=extract_attendance_data, run_id=scheduled__2024-11-24T00:00:00+00:00, execution_date=20241124T000000, start_date=20241125T084243, end_date=20241125T084243
[2024-11-25T08:42:44.012+0000] {taskinstance.py:340} INFO - ::group::Post task execution logs
[2024-11-25T08:42:44.015+0000] {standard_task_runner.py:124} ERROR - Failed to execute job 3 for task extract_attendance_data (The conn_id `attendance_api` isn't defined; 1035)
Traceback (most recent call last):
  File "/home/airflow/.local/lib/python3.12/site-packages/airflow/task/task_runner/standard_task_runner.py", line 117, in _start_by_fork
    ret = args.func(args, dag=self.dag)
          ^^^^^^^^^^^^^^^^^^^^^^^^^^^^^
  File "/home/airflow/.local/lib/python3.12/site-packages/airflow/cli/cli_config.py", line 49, in command
    return func(*args, **kwargs)
           ^^^^^^^^^^^^^^^^^^^^^
  File "/home/airflow/.local/lib/python3.12/site-packages/airflow/utils/cli.py", line 116, in wrapper
    return f(*args, **kwargs)
           ^^^^^^^^^^^^^^^^^^
  File "/home/airflow/.local/lib/python3.12/site-packages/airflow/cli/commands/task_command.py", line 483, in task_run
    task_return_code = _run_task_by_selected_method(args, _dag, ti)
                       ^^^^^^^^^^^^^^^^^^^^^^^^^^^^^^^^^^^^^^^^^^^^
  File "/home/airflow/.local/lib/python3.12/site-packages/airflow/cli/commands/task_command.py", line 256, in _run_task_by_selected_method
    return _run_raw_task(args, ti)
           ^^^^^^^^^^^^^^^^^^^^^^^
  File "/home/airflow/.local/lib/python3.12/site-packages/airflow/cli/commands/task_command.py", line 341, in _run_raw_task
    return ti._run_raw_task(
           ^^^^^^^^^^^^^^^^^
  File "/home/airflow/.local/lib/python3.12/site-packages/airflow/utils/session.py", line 97, in wrapper
    return func(*args, session=session, **kwargs)
           ^^^^^^^^^^^^^^^^^^^^^^^^^^^^^^^^^^^^^^
  File "/home/airflow/.local/lib/python3.12/site-packages/airflow/models/taskinstance.py", line 3005, in _run_raw_task
    return _run_raw_task(
           ^^^^^^^^^^^^^^
  File "/home/airflow/.local/lib/python3.12/site-packages/airflow/models/taskinstance.py", line 273, in _run_raw_task
    TaskInstance._execute_task_with_callbacks(
  File "/home/airflow/.local/lib/python3.12/site-packages/airflow/models/taskinstance.py", line 3159, in _execute_task_with_callbacks
    result = self._execute_task(context, task_orig)
             ^^^^^^^^^^^^^^^^^^^^^^^^^^^^^^^^^^^^^^
  File "/home/airflow/.local/lib/python3.12/site-packages/airflow/models/taskinstance.py", line 3183, in _execute_task
    return _execute_task(self, context, task_orig)
           ^^^^^^^^^^^^^^^^^^^^^^^^^^^^^^^^^^^^^^^
  File "/home/airflow/.local/lib/python3.12/site-packages/airflow/models/taskinstance.py", line 767, in _execute_task
    result = _execute_callable(context=context, **execute_callable_kwargs)
             ^^^^^^^^^^^^^^^^^^^^^^^^^^^^^^^^^^^^^^^^^^^^^^^^^^^^^^^^^^^^^
  File "/home/airflow/.local/lib/python3.12/site-packages/airflow/models/taskinstance.py", line 733, in _execute_callable
    return ExecutionCallableRunner(
           ^^^^^^^^^^^^^^^^^^^^^^^^
  File "/home/airflow/.local/lib/python3.12/site-packages/airflow/utils/operator_helpers.py", line 252, in run
    return self.func(*args, **kwargs)
           ^^^^^^^^^^^^^^^^^^^^^^^^^^
  File "/home/airflow/.local/lib/python3.12/site-packages/airflow/models/baseoperator.py", line 417, in wrapper
    return func(self, *args, **kwargs)
           ^^^^^^^^^^^^^^^^^^^^^^^^^^^
  File "/home/airflow/.local/lib/python3.12/site-packages/airflow/decorators/base.py", line 266, in execute
    return_value = super().execute(context)
                   ^^^^^^^^^^^^^^^^^^^^^^^^
  File "/home/airflow/.local/lib/python3.12/site-packages/airflow/models/baseoperator.py", line 417, in wrapper
    return func(self, *args, **kwargs)
           ^^^^^^^^^^^^^^^^^^^^^^^^^^^
  File "/home/airflow/.local/lib/python3.12/site-packages/airflow/operators/python.py", line 238, in execute
    return_value = self.execute_callable()
                   ^^^^^^^^^^^^^^^^^^^^^^^
  File "/home/airflow/.local/lib/python3.12/site-packages/airflow/operators/python.py", line 256, in execute_callable
    return runner.run(*self.op_args, **self.op_kwargs)
           ^^^^^^^^^^^^^^^^^^^^^^^^^^^^^^^^^^^^^^^^^^^
  File "/home/airflow/.local/lib/python3.12/site-packages/airflow/utils/operator_helpers.py", line 252, in run
    return self.func(*args, **kwargs)
           ^^^^^^^^^^^^^^^^^^^^^^^^^^
  File "/opt/airflow/dags/api_to_pgdatabase.py", line 48, in extract_attendance_data
    response=http_hook.run(endpoint)
             ^^^^^^^^^^^^^^^^^^^^^^^
  File "/home/airflow/.local/lib/python3.12/site-packages/airflow/providers/http/hooks/http.py", line 170, in run
    session = self.get_conn(headers)
              ^^^^^^^^^^^^^^^^^^^^^^
  File "/home/airflow/.local/lib/python3.12/site-packages/airflow/providers/http/hooks/http.py", line 110, in get_conn
    conn = self.get_connection(self.http_conn_id)
           ^^^^^^^^^^^^^^^^^^^^^^^^^^^^^^^^^^^^^^
  File "/home/airflow/.local/lib/python3.12/site-packages/airflow/hooks/base.py", line 83, in get_connection
    conn = Connection.get_connection_from_secrets(conn_id)
           ^^^^^^^^^^^^^^^^^^^^^^^^^^^^^^^^^^^^^^^^^^^^^^^
  File "/home/airflow/.local/lib/python3.12/site-packages/airflow/models/connection.py", line 537, in get_connection_from_secrets
    raise AirflowNotFoundException(f"The conn_id `{conn_id}` isn't defined")
airflow.exceptions.AirflowNotFoundException: The conn_id `attendance_api` isn't defined
[2024-11-25T08:42:44.071+0000] {local_task_job_runner.py:266} INFO - Task exited with return code 1
[2024-11-25T08:42:44.108+0000] {taskinstance.py:3895} INFO - 0 downstream tasks scheduled from follow-on schedule check
[2024-11-25T08:42:44.110+0000] {local_task_job_runner.py:245} INFO - ::endgroup::
