[2024-11-23T08:36:24.783+0000] {local_task_job_runner.py:123} INFO - ::group::Pre task execution logs
[2024-11-23T08:36:24.831+0000] {taskinstance.py:2613} INFO - Dependencies all met for dep_context=non-requeueable deps ti=<TaskInstance: fetch_data_from_api_to_postgresql.store_data_to_postgresql manual__2024-11-23T08:35:13.895758+00:00 [queued]>
[2024-11-23T08:36:24.860+0000] {taskinstance.py:2613} INFO - Dependencies all met for dep_context=requeueable deps ti=<TaskInstance: fetch_data_from_api_to_postgresql.store_data_to_postgresql manual__2024-11-23T08:35:13.895758+00:00 [queued]>
[2024-11-23T08:36:24.865+0000] {taskinstance.py:2866} INFO - Starting attempt 1 of 3
[2024-11-23T08:36:24.929+0000] {taskinstance.py:2889} INFO - Executing <Task(PythonOperator): store_data_to_postgresql> on 2024-11-23 08:35:13.895758+00:00
[2024-11-23T08:36:24.960+0000] {standard_task_runner.py:104} INFO - Running: ['***', 'tasks', 'run', 'fetch_data_from_api_to_postgresql', 'store_data_to_postgresql', 'manual__2024-11-23T08:35:13.895758+00:00', '--job-id', '6', '--raw', '--subdir', 'DAGS_FOLDER/api_to_pgdatabase.py', '--cfg-path', '/tmp/tmpxw0nqnz7']
[2024-11-23T08:36:24.964+0000] {logging_mixin.py:190} WARNING - /home/***/.local/lib/python3.12/site-packages/***/task/task_runner/standard_task_runner.py:70 DeprecationWarning: This process (pid=52584) is multi-threaded, use of fork() may lead to deadlocks in the child.
[2024-11-23T08:36:24.964+0000] {standard_task_runner.py:105} INFO - Job 6: Subtask store_data_to_postgresql
[2024-11-23T08:36:24.969+0000] {standard_task_runner.py:72} INFO - Started process 52588 to run task
[2024-11-23T08:36:25.166+0000] {task_command.py:467} INFO - Running <TaskInstance: fetch_data_from_api_to_postgresql.store_data_to_postgresql manual__2024-11-23T08:35:13.895758+00:00 [running]> on host 4549f6bb77d2
[2024-11-23T08:36:25.918+0000] {taskinstance.py:3132} INFO - Exporting env vars: AIRFLOW_CTX_DAG_OWNER='***' AIRFLOW_CTX_DAG_ID='fetch_data_from_api_to_postgresql' AIRFLOW_CTX_TASK_ID='store_data_to_postgresql' AIRFLOW_CTX_EXECUTION_DATE='2024-11-23T08:35:13.895758+00:00' AIRFLOW_CTX_TRY_NUMBER='1' AIRFLOW_CTX_DAG_RUN_ID='manual__2024-11-23T08:35:13.895758+00:00'
[2024-11-23T08:36:25.922+0000] {logging_mixin.py:190} INFO - Task instance is in running state
[2024-11-23T08:36:25.924+0000] {logging_mixin.py:190} INFO -  Previous state of the Task instance: queued
[2024-11-23T08:36:25.931+0000] {logging_mixin.py:190} INFO - Current task name:store_data_to_postgresql state:running start_date:2024-11-23 08:36:24.832137+00:00
[2024-11-23T08:36:25.947+0000] {logging_mixin.py:190} INFO - Dag name:fetch_data_from_api_to_postgresql and current dag run status:running
[2024-11-23T08:36:25.949+0000] {taskinstance.py:731} INFO - ::endgroup::
[2024-11-23T08:36:26.042+0000] {base.py:84} INFO - Retrieving connection 'postgres_default_2'
[2024-11-23T08:36:26.325+0000] {taskinstance.py:3311} ERROR - Task failed with exception
Traceback (most recent call last):
  File "/home/airflow/.local/lib/python3.12/site-packages/airflow/models/taskinstance.py", line 767, in _execute_task
    result = _execute_callable(context=context, **execute_callable_kwargs)
             ^^^^^^^^^^^^^^^^^^^^^^^^^^^^^^^^^^^^^^^^^^^^^^^^^^^^^^^^^^^^^
  File "/home/airflow/.local/lib/python3.12/site-packages/airflow/models/taskinstance.py", line 733, in _execute_callable
    return ExecutionCallableRunner(
           ^^^^^^^^^^^^^^^^^^^^^^^^
  File "/home/airflow/.local/lib/python3.12/site-packages/airflow/utils/operator_helpers.py", line 252, in run
    return self.func(*args, **kwargs)
           ^^^^^^^^^^^^^^^^^^^^^^^^^^
  File "/home/airflow/.local/lib/python3.12/site-packages/airflow/models/baseoperator.py", line 417, in wrapper
    return func(self, *args, **kwargs)
           ^^^^^^^^^^^^^^^^^^^^^^^^^^^
  File "/home/airflow/.local/lib/python3.12/site-packages/airflow/operators/python.py", line 238, in execute
    return_value = self.execute_callable()
                   ^^^^^^^^^^^^^^^^^^^^^^^
  File "/home/airflow/.local/lib/python3.12/site-packages/airflow/operators/python.py", line 256, in execute_callable
    return runner.run(*self.op_args, **self.op_kwargs)
           ^^^^^^^^^^^^^^^^^^^^^^^^^^^^^^^^^^^^^^^^^^^
  File "/home/airflow/.local/lib/python3.12/site-packages/airflow/utils/operator_helpers.py", line 252, in run
    return self.func(*args, **kwargs)
           ^^^^^^^^^^^^^^^^^^^^^^^^^^
  File "/opt/airflow/dags/api_to_pgdatabase.py", line 126, in store_data_to_postgresql
    cursor.execute(
psycopg2.errors.UndefinedTable: relation "attendance" does not exist
LINE 2:         INSERT INTO attendance (
                            ^

[2024-11-23T08:36:26.420+0000] {logging_mixin.py:190} INFO - Task instance in failure state
[2024-11-23T08:36:26.422+0000] {logging_mixin.py:190} INFO - Task start:2024-11-23 08:36:24.832137+00:00 end:2024-11-23 08:36:26.418786+00:00 duration:1.586649
[2024-11-23T08:36:26.426+0000] {logging_mixin.py:190} INFO - Task:<Task(PythonOperator): store_data_to_postgresql> dag:<DAG: fetch_data_from_api_to_postgresql> dagrun:<DagRun fetch_data_from_api_to_postgresql @ 2024-11-23 08:35:13.895758+00:00: manual__2024-11-23T08:35:13.895758+00:00, state:running, queued_at: 2024-11-23 08:35:14.054768+00:00. externally triggered: True>
[2024-11-23T08:36:26.434+0000] {logging_mixin.py:190} INFO - Failure caused by relation "attendance" does not exist
LINE 2:         INSERT INTO attendance (
                            ^
[2024-11-23T08:36:26.436+0000] {taskinstance.py:1225} INFO - Marking task as UP_FOR_RETRY. dag_id=fetch_data_from_api_to_postgresql, task_id=store_data_to_postgresql, run_id=manual__2024-11-23T08:35:13.895758+00:00, execution_date=20241123T083513, start_date=20241123T083624, end_date=20241123T083626
[2024-11-23T08:36:26.514+0000] {taskinstance.py:340} INFO - ::group::Post task execution logs
[2024-11-23T08:36:26.523+0000] {standard_task_runner.py:124} ERROR - Failed to execute job 6 for task store_data_to_postgresql (relation "attendance" does not exist
LINE 2:         INSERT INTO attendance (
                            ^
; 52588)
Traceback (most recent call last):
  File "/home/airflow/.local/lib/python3.12/site-packages/airflow/task/task_runner/standard_task_runner.py", line 117, in _start_by_fork
    ret = args.func(args, dag=self.dag)
          ^^^^^^^^^^^^^^^^^^^^^^^^^^^^^
  File "/home/airflow/.local/lib/python3.12/site-packages/airflow/cli/cli_config.py", line 49, in command
    return func(*args, **kwargs)
           ^^^^^^^^^^^^^^^^^^^^^
  File "/home/airflow/.local/lib/python3.12/site-packages/airflow/utils/cli.py", line 116, in wrapper
    return f(*args, **kwargs)
           ^^^^^^^^^^^^^^^^^^
  File "/home/airflow/.local/lib/python3.12/site-packages/airflow/cli/commands/task_command.py", line 483, in task_run
    task_return_code = _run_task_by_selected_method(args, _dag, ti)
                       ^^^^^^^^^^^^^^^^^^^^^^^^^^^^^^^^^^^^^^^^^^^^
  File "/home/airflow/.local/lib/python3.12/site-packages/airflow/cli/commands/task_command.py", line 256, in _run_task_by_selected_method
    return _run_raw_task(args, ti)
           ^^^^^^^^^^^^^^^^^^^^^^^
  File "/home/airflow/.local/lib/python3.12/site-packages/airflow/cli/commands/task_command.py", line 341, in _run_raw_task
    return ti._run_raw_task(
           ^^^^^^^^^^^^^^^^^
  File "/home/airflow/.local/lib/python3.12/site-packages/airflow/utils/session.py", line 97, in wrapper
    return func(*args, session=session, **kwargs)
           ^^^^^^^^^^^^^^^^^^^^^^^^^^^^^^^^^^^^^^
  File "/home/airflow/.local/lib/python3.12/site-packages/airflow/models/taskinstance.py", line 3005, in _run_raw_task
    return _run_raw_task(
           ^^^^^^^^^^^^^^
  File "/home/airflow/.local/lib/python3.12/site-packages/airflow/models/taskinstance.py", line 273, in _run_raw_task
    TaskInstance._execute_task_with_callbacks(
  File "/home/airflow/.local/lib/python3.12/site-packages/airflow/models/taskinstance.py", line 3159, in _execute_task_with_callbacks
    result = self._execute_task(context, task_orig)
             ^^^^^^^^^^^^^^^^^^^^^^^^^^^^^^^^^^^^^^
  File "/home/airflow/.local/lib/python3.12/site-packages/airflow/models/taskinstance.py", line 3183, in _execute_task
    return _execute_task(self, context, task_orig)
           ^^^^^^^^^^^^^^^^^^^^^^^^^^^^^^^^^^^^^^^
  File "/home/airflow/.local/lib/python3.12/site-packages/airflow/models/taskinstance.py", line 767, in _execute_task
    result = _execute_callable(context=context, **execute_callable_kwargs)
             ^^^^^^^^^^^^^^^^^^^^^^^^^^^^^^^^^^^^^^^^^^^^^^^^^^^^^^^^^^^^^
  File "/home/airflow/.local/lib/python3.12/site-packages/airflow/models/taskinstance.py", line 733, in _execute_callable
    return ExecutionCallableRunner(
           ^^^^^^^^^^^^^^^^^^^^^^^^
  File "/home/airflow/.local/lib/python3.12/site-packages/airflow/utils/operator_helpers.py", line 252, in run
    return self.func(*args, **kwargs)
           ^^^^^^^^^^^^^^^^^^^^^^^^^^
  File "/home/airflow/.local/lib/python3.12/site-packages/airflow/models/baseoperator.py", line 417, in wrapper
    return func(self, *args, **kwargs)
           ^^^^^^^^^^^^^^^^^^^^^^^^^^^
  File "/home/airflow/.local/lib/python3.12/site-packages/airflow/operators/python.py", line 238, in execute
    return_value = self.execute_callable()
                   ^^^^^^^^^^^^^^^^^^^^^^^
  File "/home/airflow/.local/lib/python3.12/site-packages/airflow/operators/python.py", line 256, in execute_callable
    return runner.run(*self.op_args, **self.op_kwargs)
           ^^^^^^^^^^^^^^^^^^^^^^^^^^^^^^^^^^^^^^^^^^^
  File "/home/airflow/.local/lib/python3.12/site-packages/airflow/utils/operator_helpers.py", line 252, in run
    return self.func(*args, **kwargs)
           ^^^^^^^^^^^^^^^^^^^^^^^^^^
  File "/opt/airflow/dags/api_to_pgdatabase.py", line 126, in store_data_to_postgresql
    cursor.execute(
psycopg2.errors.UndefinedTable: relation "attendance" does not exist
LINE 2:         INSERT INTO attendance (
                            ^

[2024-11-23T08:36:26.608+0000] {local_task_job_runner.py:266} INFO - Task exited with return code 1
[2024-11-23T08:36:26.675+0000] {taskinstance.py:3895} INFO - 0 downstream tasks scheduled from follow-on schedule check
[2024-11-23T08:36:26.681+0000] {local_task_job_runner.py:245} INFO - ::endgroup::
